<?xml version="1.0" ?>
<!-- =================================================================================== -->
<!-- |    This document was autogenerated by xacro from robotino.urdf.xacro            | -->
<!-- |    EDITING THIS FILE BY HAND IS NOT RECOMMENDED                                 | -->
<!-- =================================================================================== -->
<robot name="robotino">
  <!-- 1.33297475178 -->
  <!-- Used for fixing robot to the world in Gazebo -->
  <link name="base_link">
    <!-- <xacro:inertial_cylinder mass="${WHEEL_MASS}" height="${WHEEL_HEIGHT}" radius="${WHEEL_RADIUS}">
            <origin xyz="0 0 0"/>
        </xacro:inertial_cylinder> -->
  </link>
  <link name="chassis_link">
    <inertial>
      <origin xyz="0 0 0"/>
      <mass value="20"/>
      <inertia ixx="0.16616666666666666" ixy="0.0" ixz="0.0" iyy="0.16616666666666666" iyz="0.0" izz="0.32399999999999995"/>
    </inertial>
    <visual>
      <!-- <origin xyz="0 0 ${BASE_HEIGHT}" rpy="0 0 0" /> -->
      <origin rpy="0 0 1.570795" xyz="0.01 0 0"/>
      <geometry>
        <!-- <cylinder radius="${BASE_RADIUS}" length="${BASE_HEIGHT}"/> -->
        <mesh filename="package://robotino_roller/description/mesh/robotino_base.dae" scale="0.01 0.01 0.01"/>
      </geometry>
    </visual>
    <collision>
      <origin rpy="0 0 0" xyz="0 0 0.05"/>
      <geometry>
        <cylinder length="0.05" radius="0.18"/>
      </geometry>
    </collision>
  </link>
  <joint name="chassis_joint" type="fixed">
    <parent link="base_link"/>
    <child link="chassis_link"/>
    <origin xyz="0 0 0"/>
  </joint>
  <gazebo reference="chassis">
    <material>Gazebo/White</material>
    <turnGravityOff>false</turnGravityOff>
  </gazebo>
  <link name="wheel0_link">
    <inertial>
      <origin xyz="0 0 0"/>
      <mass value="1.26"/>
      <inertia ixx="0.000672" ixy="0.0" ixz="0.0" iyy="0.000672" iyz="0.0" izz="0.001008"/>
    </inertial>
    <visual>
      <geometry>
        <mesh filename="package://robotino_roller/description/mesh/rim01.stl"/>
        <!-- <mesh filename="package://robotino_roller/description/mesh/roda.stl" scale="${WHEEL_SCALE} ${WHEEL_SCALE} ${WHEEL_SCALE}"/> -->
      </geometry>
    </visual>
    <collision>
      <geometry>
        <mesh filename="package://robotino_roller/description/mesh/rim01.stl"/>
        <!-- <mesh filename="package://robotino_roller/description/mesh/roda.stl" scale="${WHEEL_SCALE} ${WHEEL_SCALE} ${WHEEL_SCALE}"/> -->
      </geometry>
    </collision>
  </link>
  <joint name="wheel0_joint" type="continuous">
    <parent link="chassis_link"/>
    <child link="wheel0_link"/>
    <origin rpy="1.570795 0 -0.5235983333333333" xyz="0.065 0.11 0.04"/>
    <axis xyz="0 0 1"/>
  </joint>
  <gazebo reference="wheel0_link">
    <material>Gazebo/Yellow</material>
    <turnGravityOff>false</turnGravityOff>
  </gazebo>
  <link name="roller_upfront_wheel0_link">
    <inertial>
      <origin xyz="0 0 0"/>
      <mass value="0.1"/>
      <inertia ixx="7.0710067480021846e-06" ixy="0.0" ixz="0.0" iyy="7.0710067480021846e-06" iyz="0.0" izz="3.4517509961418232e-06"/>
    </inertial>
    <visual>
      <geometry>
        <mesh filename="package://robotino_roller/description/mesh/roller01.stl"/>
        <!-- <mesh filename="package://robotino_roller/description/mesh/rolamento.stl" scale="${WHEEL_SCALE} ${WHEEL_SCALE} ${WHEEL_SCALE}"/> -->
      </geometry>
    </visual>
    <collision>
      <geometry>
        <mesh filename="package://robotino_roller/description/mesh/roller01.stl"/>
        <!-- <mesh filename="package://robotino_roller/description/mesh/rolamento.stl" scale="${WHEEL_SCALE} ${WHEEL_SCALE} ${WHEEL_SCALE}"/> -->
      </geometry>
    </collision>
  </link>
  <gazebo reference="roller_upfront_wheel0_link">
    <material>Gazebo/Black</material>
    <mu1 value="2.5"/>
    <mu2 value="2.5"/>
    <kp value="5000"/>
    <kd value="10"/>
  </gazebo>
  <joint name="roller_upfront_wheel0_joint" type="continuous">
    <parent link="wheel0_link"/>
    <child link="roller_upfront_wheel0_link"/>
    <axis xyz="0 0 1"/>
    <origin rpy="-1.570796326794896 0 1.570796326794896" xyz="0.0 0.0320713725278268 0.007331361134789999"/>
    <!--<dynamics damping="0.001"/>-->
  </joint>
  <link name="roller_rightupfront_wheel0_link">
    <inertial>
      <origin xyz="0 0 0"/>
      <mass value="0.1"/>
      <inertia ixx="7.0710067480021846e-06" ixy="0.0" ixz="0.0" iyy="7.0710067480021846e-06" iyz="0.0" izz="3.4517509961418232e-06"/>
    </inertial>
    <visual>
      <geometry>
        <mesh filename="package://robotino_roller/description/mesh/roller01.stl"/>
        <!-- <mesh filename="package://robotino_roller/description/mesh/rolamento.stl" scale="${WHEEL_SCALE} ${WHEEL_SCALE} ${WHEEL_SCALE}"/> -->
      </geometry>
    </visual>
    <collision>
      <geometry>
        <mesh filename="package://robotino_roller/description/mesh/roller01.stl"/>
        <!-- <mesh filename="package://robotino_roller/description/mesh/rolamento.stl" scale="${WHEEL_SCALE} ${WHEEL_SCALE} ${WHEEL_SCALE}"/> -->
      </geometry>
    </collision>
  </link>
  <gazebo reference="roller_rightupfront_wheel0_link">
    <material>Gazebo/Black</material>
    <mu1 value="2.5"/>
    <mu2 value="2.5"/>
    <kp value="5000"/>
    <kd value="10"/>
  </gazebo>
  <joint name="roller_rightupfront_wheel0_joint" type="continuous">
    <parent link="wheel0_link"/>
    <child link="roller_rightupfront_wheel0_link"/>
    <axis xyz="0 0 1"/>
    <origin rpy="-1.570796326794896 0 -2.82743" xyz="0.0304984623207264 0.0099040024057254 0.007331361134789999"/>
    <!--<dynamics damping="0.001"/>-->
  </joint>
  <link name="roller_leftupfront_wheel0_link">
    <inertial>
      <origin xyz="0 0 0"/>
      <mass value="0.1"/>
      <inertia ixx="7.0710067480021846e-06" ixy="0.0" ixz="0.0" iyy="7.0710067480021846e-06" iyz="0.0" izz="3.4517509961418232e-06"/>
    </inertial>
    <visual>
      <geometry>
        <mesh filename="package://robotino_roller/description/mesh/roller01.stl"/>
        <!-- <mesh filename="package://robotino_roller/description/mesh/rolamento.stl" scale="${WHEEL_SCALE} ${WHEEL_SCALE} ${WHEEL_SCALE}"/> -->
      </geometry>
    </visual>
    <collision>
      <geometry>
        <mesh filename="package://robotino_roller/description/mesh/roller01.stl"/>
        <!-- <mesh filename="package://robotino_roller/description/mesh/rolamento.stl" scale="${WHEEL_SCALE} ${WHEEL_SCALE} ${WHEEL_SCALE}"/> -->
      </geometry>
    </collision>
  </link>
  <gazebo reference="roller_leftupfront_wheel0_link">
    <material>Gazebo/Black</material>
    <mu1 value="2.5"/>
    <mu2 value="2.5"/>
    <kp value="5000"/>
    <kd value="10"/>
  </gazebo>
  <joint name="roller_leftupfront_wheel0_joint" type="continuous">
    <parent link="wheel0_link"/>
    <child link="roller_leftupfront_wheel0_link"/>
    <axis xyz="0 0 1"/>
    <origin rpy="-1.570796326794896 0 2.82743" xyz="-0.0304984623207264 0.0099040024057254 0.007331361134789999"/>
    <!--<dynamics damping="0.001"/>-->
  </joint>
  <link name="roller_rightdownfront_wheel0_link">
    <inertial>
      <origin xyz="0 0 0"/>
      <mass value="0.1"/>
      <inertia ixx="7.0710067480021846e-06" ixy="0.0" ixz="0.0" iyy="7.0710067480021846e-06" iyz="0.0" izz="3.4517509961418232e-06"/>
    </inertial>
    <visual>
      <geometry>
        <mesh filename="package://robotino_roller/description/mesh/roller01.stl"/>
        <!-- <mesh filename="package://robotino_roller/description/mesh/rolamento.stl" scale="${WHEEL_SCALE} ${WHEEL_SCALE} ${WHEEL_SCALE}"/> -->
      </geometry>
    </visual>
    <collision>
      <geometry>
        <mesh filename="package://robotino_roller/description/mesh/roller01.stl"/>
        <!-- <mesh filename="package://robotino_roller/description/mesh/rolamento.stl" scale="${WHEEL_SCALE} ${WHEEL_SCALE} ${WHEEL_SCALE}"/> -->
      </geometry>
    </collision>
  </link>
  <gazebo reference="roller_rightdownfront_wheel0_link">
    <material>Gazebo/Black</material>
    <mu1 value="2.5"/>
    <mu2 value="2.5"/>
    <kp value="5000"/>
    <kd value="10"/>
  </gazebo>
  <joint name="roller_rightdownfront_wheel0_joint" type="continuous">
    <parent link="wheel0_link"/>
    <child link="roller_rightdownfront_wheel0_link"/>
    <axis xyz="0 0 1"/>
    <origin rpy="-1.570796326794896 0 -0.959931" xyz="0.018848262990169198 -0.0259530184171566 0.007331361134789999"/>
    <!--<dynamics damping="0.001"/>-->
  </joint>
  <link name="roller_lefttdownfront_wheel0_link">
    <inertial>
      <origin xyz="0 0 0"/>
      <mass value="0.1"/>
      <inertia ixx="7.0710067480021846e-06" ixy="0.0" ixz="0.0" iyy="7.0710067480021846e-06" iyz="0.0" izz="3.4517509961418232e-06"/>
    </inertial>
    <visual>
      <geometry>
        <mesh filename="package://robotino_roller/description/mesh/roller01.stl"/>
        <!-- <mesh filename="package://robotino_roller/description/mesh/rolamento.stl" scale="${WHEEL_SCALE} ${WHEEL_SCALE} ${WHEEL_SCALE}"/> -->
      </geometry>
    </visual>
    <collision>
      <geometry>
        <mesh filename="package://robotino_roller/description/mesh/roller01.stl"/>
        <!-- <mesh filename="package://robotino_roller/description/mesh/rolamento.stl" scale="${WHEEL_SCALE} ${WHEEL_SCALE} ${WHEEL_SCALE}"/> -->
      </geometry>
    </collision>
  </link>
  <gazebo reference="roller_lefttdownfront_wheel0_link">
    <material>Gazebo/Black</material>
    <mu1 value="2.5"/>
    <mu2 value="2.5"/>
    <kp value="5000"/>
    <kd value="10"/>
  </gazebo>
  <joint name="roller_lefttdownfront_wheel0_joint" type="continuous">
    <parent link="wheel0_link"/>
    <child link="roller_lefttdownfront_wheel0_link"/>
    <axis xyz="0 0 1"/>
    <origin rpy="-1.570796326794896 0 0.959931" xyz="-0.018848262990169198 -0.0259530184171566 0.007331361134789999"/>
    <!--<dynamics damping="0.001"/>-->
  </joint>
  <link name="roller_upback_wheel0_link">
    <inertial>
      <origin xyz="0 0 0"/>
      <mass value="0.1"/>
      <inertia ixx="7.0710067480021846e-06" ixy="0.0" ixz="0.0" iyy="7.0710067480021846e-06" iyz="0.0" izz="3.4517509961418232e-06"/>
    </inertial>
    <visual>
      <geometry>
        <mesh filename="package://robotino_roller/description/mesh/roller01.stl"/>
        <!-- <mesh filename="package://robotino_roller/description/mesh/rolamento.stl" scale="${WHEEL_SCALE} ${WHEEL_SCALE} ${WHEEL_SCALE}"/> -->
      </geometry>
    </visual>
    <collision>
      <geometry>
        <mesh filename="package://robotino_roller/description/mesh/roller01.stl"/>
        <!-- <mesh filename="package://robotino_roller/description/mesh/rolamento.stl" scale="${WHEEL_SCALE} ${WHEEL_SCALE} ${WHEEL_SCALE}"/> -->
      </geometry>
    </collision>
  </link>
  <gazebo reference="roller_upback_wheel0_link">
    <material>Gazebo/Black</material>
    <mu1 value="2.5"/>
    <mu2 value="2.5"/>
    <kp value="5000"/>
    <kd value="10"/>
  </gazebo>
  <joint name="roller_upback_wheel0_joint" type="continuous">
    <parent link="wheel0_link"/>
    <child link="roller_upback_wheel0_link"/>
    <axis xyz="0 0 1"/>
    <origin rpy="-1.570796326794896 0 1.570796326794896" xyz="0.0 -0.0320713725278268 -0.008531038411392"/>
    <!--<dynamics damping="0.001"/>-->
  </joint>
  <link name="roller_rightupback_wheel0_link">
    <inertial>
      <origin xyz="0 0 0"/>
      <mass value="0.1"/>
      <inertia ixx="7.0710067480021846e-06" ixy="0.0" ixz="0.0" iyy="7.0710067480021846e-06" iyz="0.0" izz="3.4517509961418232e-06"/>
    </inertial>
    <visual>
      <geometry>
        <mesh filename="package://robotino_roller/description/mesh/roller01.stl"/>
        <!-- <mesh filename="package://robotino_roller/description/mesh/rolamento.stl" scale="${WHEEL_SCALE} ${WHEEL_SCALE} ${WHEEL_SCALE}"/> -->
      </geometry>
    </visual>
    <collision>
      <geometry>
        <mesh filename="package://robotino_roller/description/mesh/roller01.stl"/>
        <!-- <mesh filename="package://robotino_roller/description/mesh/rolamento.stl" scale="${WHEEL_SCALE} ${WHEEL_SCALE} ${WHEEL_SCALE}"/> -->
      </geometry>
    </collision>
  </link>
  <gazebo reference="roller_rightupback_wheel0_link">
    <material>Gazebo/Black</material>
    <mu1 value="2.5"/>
    <mu2 value="2.5"/>
    <kp value="5000"/>
    <kd value="10"/>
  </gazebo>
  <joint name="roller_rightupback_wheel0_joint" type="continuous">
    <parent link="wheel0_link"/>
    <child link="roller_rightupback_wheel0_link"/>
    <axis xyz="0 0 1"/>
    <origin rpy="-1.570796326794896 0 -2.82743" xyz="-0.0304984623207264 -0.0099040024057254 -0.008531038411392"/>
    <!--<dynamics damping="0.001"/>-->
  </joint>
  <link name="roller_leftupback_wheel0_link">
    <inertial>
      <origin xyz="0 0 0"/>
      <mass value="0.1"/>
      <inertia ixx="7.0710067480021846e-06" ixy="0.0" ixz="0.0" iyy="7.0710067480021846e-06" iyz="0.0" izz="3.4517509961418232e-06"/>
    </inertial>
    <visual>
      <geometry>
        <mesh filename="package://robotino_roller/description/mesh/roller01.stl"/>
        <!-- <mesh filename="package://robotino_roller/description/mesh/rolamento.stl" scale="${WHEEL_SCALE} ${WHEEL_SCALE} ${WHEEL_SCALE}"/> -->
      </geometry>
    </visual>
    <collision>
      <geometry>
        <mesh filename="package://robotino_roller/description/mesh/roller01.stl"/>
        <!-- <mesh filename="package://robotino_roller/description/mesh/rolamento.stl" scale="${WHEEL_SCALE} ${WHEEL_SCALE} ${WHEEL_SCALE}"/> -->
      </geometry>
    </collision>
  </link>
  <gazebo reference="roller_leftupback_wheel0_link">
    <material>Gazebo/Black</material>
    <mu1 value="2.5"/>
    <mu2 value="2.5"/>
    <kp value="5000"/>
    <kd value="10"/>
  </gazebo>
  <joint name="roller_leftupback_wheel0_joint" type="continuous">
    <parent link="wheel0_link"/>
    <child link="roller_leftupback_wheel0_link"/>
    <axis xyz="0 0 1"/>
    <origin rpy="-1.570796326794896 0 2.82743" xyz="0.0304984623207264 -0.0099040024057254 -0.008531038411392"/>
    <!--<dynamics damping="0.001"/>-->
  </joint>
  <link name="roller_rightdownback_wheel0_link">
    <inertial>
      <origin xyz="0 0 0"/>
      <mass value="0.1"/>
      <inertia ixx="7.0710067480021846e-06" ixy="0.0" ixz="0.0" iyy="7.0710067480021846e-06" iyz="0.0" izz="3.4517509961418232e-06"/>
    </inertial>
    <visual>
      <geometry>
        <mesh filename="package://robotino_roller/description/mesh/roller01.stl"/>
        <!-- <mesh filename="package://robotino_roller/description/mesh/rolamento.stl" scale="${WHEEL_SCALE} ${WHEEL_SCALE} ${WHEEL_SCALE}"/> -->
      </geometry>
    </visual>
    <collision>
      <geometry>
        <mesh filename="package://robotino_roller/description/mesh/roller01.stl"/>
        <!-- <mesh filename="package://robotino_roller/description/mesh/rolamento.stl" scale="${WHEEL_SCALE} ${WHEEL_SCALE} ${WHEEL_SCALE}"/> -->
      </geometry>
    </collision>
  </link>
  <gazebo reference="roller_rightdownback_wheel0_link">
    <material>Gazebo/Black</material>
    <mu1 value="2.5"/>
    <mu2 value="2.5"/>
    <kp value="5000"/>
    <kd value="10"/>
  </gazebo>
  <joint name="roller_rightdownback_wheel0_joint" type="continuous">
    <parent link="wheel0_link"/>
    <child link="roller_rightdownback_wheel0_link"/>
    <axis xyz="0 0 1"/>
    <origin rpy="-1.570796326794896 0 -0.959931" xyz="-0.018848262990169198 0.0259530184171566 -0.008531038411392"/>
    <!--<dynamics damping="0.001"/>-->
  </joint>
  <link name="roller_lefttdownback_wheel0_link">
    <inertial>
      <origin xyz="0 0 0"/>
      <mass value="0.1"/>
      <inertia ixx="7.0710067480021846e-06" ixy="0.0" ixz="0.0" iyy="7.0710067480021846e-06" iyz="0.0" izz="3.4517509961418232e-06"/>
    </inertial>
    <visual>
      <geometry>
        <mesh filename="package://robotino_roller/description/mesh/roller01.stl"/>
        <!-- <mesh filename="package://robotino_roller/description/mesh/rolamento.stl" scale="${WHEEL_SCALE} ${WHEEL_SCALE} ${WHEEL_SCALE}"/> -->
      </geometry>
    </visual>
    <collision>
      <geometry>
        <mesh filename="package://robotino_roller/description/mesh/roller01.stl"/>
        <!-- <mesh filename="package://robotino_roller/description/mesh/rolamento.stl" scale="${WHEEL_SCALE} ${WHEEL_SCALE} ${WHEEL_SCALE}"/> -->
      </geometry>
    </collision>
  </link>
  <gazebo reference="roller_lefttdownback_wheel0_link">
    <material>Gazebo/Black</material>
    <mu1 value="2.5"/>
    <mu2 value="2.5"/>
    <kp value="5000"/>
    <kd value="10"/>
  </gazebo>
  <joint name="roller_lefttdownback_wheel0_joint" type="continuous">
    <parent link="wheel0_link"/>
    <child link="roller_lefttdownback_wheel0_link"/>
    <axis xyz="0 0 1"/>
    <origin rpy="-1.570796326794896 0 0.959931" xyz="0.018848262990169198 0.0259530184171566 -0.008531038411392"/>
    <!--<dynamics damping="0.001"/>-->
  </joint>
  <transmission name="wheel0_transmission">
    <type>transmission_interface/SimpleTransmission</type>
    <joint name="wheel0_joint">
      <hardwareInterface>hardware_interface/EffortJointInterface</hardwareInterface>
    </joint>
    <actuator name="wheel0_motor">
      <hardwareInterface>hardware_interface/EffortJointInterface</hardwareInterface>
      <mechanicalReduction>1</mechanicalReduction>
    </actuator>
  </transmission>
  <link name="wheel1_link">
    <inertial>
      <origin xyz="0 0 0"/>
      <mass value="1.26"/>
      <inertia ixx="0.000672" ixy="0.0" ixz="0.0" iyy="0.000672" iyz="0.0" izz="0.001008"/>
    </inertial>
    <visual>
      <geometry>
        <mesh filename="package://robotino_roller/description/mesh/rim01.stl"/>
        <!-- <mesh filename="package://robotino_roller/description/mesh/roda.stl" scale="${WHEEL_SCALE} ${WHEEL_SCALE} ${WHEEL_SCALE}"/> -->
      </geometry>
    </visual>
    <collision>
      <geometry>
        <mesh filename="package://robotino_roller/description/mesh/rim01.stl"/>
        <!-- <mesh filename="package://robotino_roller/description/mesh/roda.stl" scale="${WHEEL_SCALE} ${WHEEL_SCALE} ${WHEEL_SCALE}"/> -->
      </geometry>
    </collision>
  </link>
  <joint name="wheel1_joint" type="continuous">
    <parent link="chassis_link"/>
    <child link="wheel1_link"/>
    <origin rpy="1.570795 0 1.570795" xyz="-0.13 0 0.04"/>
    <axis xyz="0 0 1"/>
  </joint>
  <gazebo reference="wheel1_link">
    <material>Gazebo/Yellow</material>
    <turnGravityOff>false</turnGravityOff>
  </gazebo>
  <link name="roller_upfront_wheel1_link">
    <inertial>
      <origin xyz="0 0 0"/>
      <mass value="0.1"/>
      <inertia ixx="7.0710067480021846e-06" ixy="0.0" ixz="0.0" iyy="7.0710067480021846e-06" iyz="0.0" izz="3.4517509961418232e-06"/>
    </inertial>
    <visual>
      <geometry>
        <mesh filename="package://robotino_roller/description/mesh/roller01.stl"/>
        <!-- <mesh filename="package://robotino_roller/description/mesh/rolamento.stl" scale="${WHEEL_SCALE} ${WHEEL_SCALE} ${WHEEL_SCALE}"/> -->
      </geometry>
    </visual>
    <collision>
      <geometry>
        <mesh filename="package://robotino_roller/description/mesh/roller01.stl"/>
        <!-- <mesh filename="package://robotino_roller/description/mesh/rolamento.stl" scale="${WHEEL_SCALE} ${WHEEL_SCALE} ${WHEEL_SCALE}"/> -->
      </geometry>
    </collision>
  </link>
  <gazebo reference="roller_upfront_wheel1_link">
    <material>Gazebo/Black</material>
    <mu1 value="2.5"/>
    <mu2 value="2.5"/>
    <kp value="5000"/>
    <kd value="10"/>
  </gazebo>
  <joint name="roller_upfront_wheel1_joint" type="continuous">
    <parent link="wheel1_link"/>
    <child link="roller_upfront_wheel1_link"/>
    <axis xyz="0 0 1"/>
    <origin rpy="-1.570796326794896 0 1.570796326794896" xyz="0.0 0.0320713725278268 0.007331361134789999"/>
    <!--<dynamics damping="0.001"/>-->
  </joint>
  <link name="roller_rightupfront_wheel1_link">
    <inertial>
      <origin xyz="0 0 0"/>
      <mass value="0.1"/>
      <inertia ixx="7.0710067480021846e-06" ixy="0.0" ixz="0.0" iyy="7.0710067480021846e-06" iyz="0.0" izz="3.4517509961418232e-06"/>
    </inertial>
    <visual>
      <geometry>
        <mesh filename="package://robotino_roller/description/mesh/roller01.stl"/>
        <!-- <mesh filename="package://robotino_roller/description/mesh/rolamento.stl" scale="${WHEEL_SCALE} ${WHEEL_SCALE} ${WHEEL_SCALE}"/> -->
      </geometry>
    </visual>
    <collision>
      <geometry>
        <mesh filename="package://robotino_roller/description/mesh/roller01.stl"/>
        <!-- <mesh filename="package://robotino_roller/description/mesh/rolamento.stl" scale="${WHEEL_SCALE} ${WHEEL_SCALE} ${WHEEL_SCALE}"/> -->
      </geometry>
    </collision>
  </link>
  <gazebo reference="roller_rightupfront_wheel1_link">
    <material>Gazebo/Black</material>
    <mu1 value="2.5"/>
    <mu2 value="2.5"/>
    <kp value="5000"/>
    <kd value="10"/>
  </gazebo>
  <joint name="roller_rightupfront_wheel1_joint" type="continuous">
    <parent link="wheel1_link"/>
    <child link="roller_rightupfront_wheel1_link"/>
    <axis xyz="0 0 1"/>
    <origin rpy="-1.570796326794896 0 -2.82743" xyz="0.0304984623207264 0.0099040024057254 0.007331361134789999"/>
    <!--<dynamics damping="0.001"/>-->
  </joint>
  <link name="roller_leftupfront_wheel1_link">
    <inertial>
      <origin xyz="0 0 0"/>
      <mass value="0.1"/>
      <inertia ixx="7.0710067480021846e-06" ixy="0.0" ixz="0.0" iyy="7.0710067480021846e-06" iyz="0.0" izz="3.4517509961418232e-06"/>
    </inertial>
    <visual>
      <geometry>
        <mesh filename="package://robotino_roller/description/mesh/roller01.stl"/>
        <!-- <mesh filename="package://robotino_roller/description/mesh/rolamento.stl" scale="${WHEEL_SCALE} ${WHEEL_SCALE} ${WHEEL_SCALE}"/> -->
      </geometry>
    </visual>
    <collision>
      <geometry>
        <mesh filename="package://robotino_roller/description/mesh/roller01.stl"/>
        <!-- <mesh filename="package://robotino_roller/description/mesh/rolamento.stl" scale="${WHEEL_SCALE} ${WHEEL_SCALE} ${WHEEL_SCALE}"/> -->
      </geometry>
    </collision>
  </link>
  <gazebo reference="roller_leftupfront_wheel1_link">
    <material>Gazebo/Black</material>
    <mu1 value="2.5"/>
    <mu2 value="2.5"/>
    <kp value="5000"/>
    <kd value="10"/>
  </gazebo>
  <joint name="roller_leftupfront_wheel1_joint" type="continuous">
    <parent link="wheel1_link"/>
    <child link="roller_leftupfront_wheel1_link"/>
    <axis xyz="0 0 1"/>
    <origin rpy="-1.570796326794896 0 2.82743" xyz="-0.0304984623207264 0.0099040024057254 0.007331361134789999"/>
    <!--<dynamics damping="0.001"/>-->
  </joint>
  <link name="roller_rightdownfront_wheel1_link">
    <inertial>
      <origin xyz="0 0 0"/>
      <mass value="0.1"/>
      <inertia ixx="7.0710067480021846e-06" ixy="0.0" ixz="0.0" iyy="7.0710067480021846e-06" iyz="0.0" izz="3.4517509961418232e-06"/>
    </inertial>
    <visual>
      <geometry>
        <mesh filename="package://robotino_roller/description/mesh/roller01.stl"/>
        <!-- <mesh filename="package://robotino_roller/description/mesh/rolamento.stl" scale="${WHEEL_SCALE} ${WHEEL_SCALE} ${WHEEL_SCALE}"/> -->
      </geometry>
    </visual>
    <collision>
      <geometry>
        <mesh filename="package://robotino_roller/description/mesh/roller01.stl"/>
        <!-- <mesh filename="package://robotino_roller/description/mesh/rolamento.stl" scale="${WHEEL_SCALE} ${WHEEL_SCALE} ${WHEEL_SCALE}"/> -->
      </geometry>
    </collision>
  </link>
  <gazebo reference="roller_rightdownfront_wheel1_link">
    <material>Gazebo/Black</material>
    <mu1 value="2.5"/>
    <mu2 value="2.5"/>
    <kp value="5000"/>
    <kd value="10"/>
  </gazebo>
  <joint name="roller_rightdownfront_wheel1_joint" type="continuous">
    <parent link="wheel1_link"/>
    <child link="roller_rightdownfront_wheel1_link"/>
    <axis xyz="0 0 1"/>
    <origin rpy="-1.570796326794896 0 -0.959931" xyz="0.018848262990169198 -0.0259530184171566 0.007331361134789999"/>
    <!--<dynamics damping="0.001"/>-->
  </joint>
  <link name="roller_lefttdownfront_wheel1_link">
    <inertial>
      <origin xyz="0 0 0"/>
      <mass value="0.1"/>
      <inertia ixx="7.0710067480021846e-06" ixy="0.0" ixz="0.0" iyy="7.0710067480021846e-06" iyz="0.0" izz="3.4517509961418232e-06"/>
    </inertial>
    <visual>
      <geometry>
        <mesh filename="package://robotino_roller/description/mesh/roller01.stl"/>
        <!-- <mesh filename="package://robotino_roller/description/mesh/rolamento.stl" scale="${WHEEL_SCALE} ${WHEEL_SCALE} ${WHEEL_SCALE}"/> -->
      </geometry>
    </visual>
    <collision>
      <geometry>
        <mesh filename="package://robotino_roller/description/mesh/roller01.stl"/>
        <!-- <mesh filename="package://robotino_roller/description/mesh/rolamento.stl" scale="${WHEEL_SCALE} ${WHEEL_SCALE} ${WHEEL_SCALE}"/> -->
      </geometry>
    </collision>
  </link>
  <gazebo reference="roller_lefttdownfront_wheel1_link">
    <material>Gazebo/Black</material>
    <mu1 value="2.5"/>
    <mu2 value="2.5"/>
    <kp value="5000"/>
    <kd value="10"/>
  </gazebo>
  <joint name="roller_lefttdownfront_wheel1_joint" type="continuous">
    <parent link="wheel1_link"/>
    <child link="roller_lefttdownfront_wheel1_link"/>
    <axis xyz="0 0 1"/>
    <origin rpy="-1.570796326794896 0 0.959931" xyz="-0.018848262990169198 -0.0259530184171566 0.007331361134789999"/>
    <!--<dynamics damping="0.001"/>-->
  </joint>
  <link name="roller_upback_wheel1_link">
    <inertial>
      <origin xyz="0 0 0"/>
      <mass value="0.1"/>
      <inertia ixx="7.0710067480021846e-06" ixy="0.0" ixz="0.0" iyy="7.0710067480021846e-06" iyz="0.0" izz="3.4517509961418232e-06"/>
    </inertial>
    <visual>
      <geometry>
        <mesh filename="package://robotino_roller/description/mesh/roller01.stl"/>
        <!-- <mesh filename="package://robotino_roller/description/mesh/rolamento.stl" scale="${WHEEL_SCALE} ${WHEEL_SCALE} ${WHEEL_SCALE}"/> -->
      </geometry>
    </visual>
    <collision>
      <geometry>
        <mesh filename="package://robotino_roller/description/mesh/roller01.stl"/>
        <!-- <mesh filename="package://robotino_roller/description/mesh/rolamento.stl" scale="${WHEEL_SCALE} ${WHEEL_SCALE} ${WHEEL_SCALE}"/> -->
      </geometry>
    </collision>
  </link>
  <gazebo reference="roller_upback_wheel1_link">
    <material>Gazebo/Black</material>
    <mu1 value="2.5"/>
    <mu2 value="2.5"/>
    <kp value="5000"/>
    <kd value="10"/>
  </gazebo>
  <joint name="roller_upback_wheel1_joint" type="continuous">
    <parent link="wheel1_link"/>
    <child link="roller_upback_wheel1_link"/>
    <axis xyz="0 0 1"/>
    <origin rpy="-1.570796326794896 0 1.570796326794896" xyz="0.0 -0.0320713725278268 -0.008531038411392"/>
    <!--<dynamics damping="0.001"/>-->
  </joint>
  <link name="roller_rightupback_wheel1_link">
    <inertial>
      <origin xyz="0 0 0"/>
      <mass value="0.1"/>
      <inertia ixx="7.0710067480021846e-06" ixy="0.0" ixz="0.0" iyy="7.0710067480021846e-06" iyz="0.0" izz="3.4517509961418232e-06"/>
    </inertial>
    <visual>
      <geometry>
        <mesh filename="package://robotino_roller/description/mesh/roller01.stl"/>
        <!-- <mesh filename="package://robotino_roller/description/mesh/rolamento.stl" scale="${WHEEL_SCALE} ${WHEEL_SCALE} ${WHEEL_SCALE}"/> -->
      </geometry>
    </visual>
    <collision>
      <geometry>
        <mesh filename="package://robotino_roller/description/mesh/roller01.stl"/>
        <!-- <mesh filename="package://robotino_roller/description/mesh/rolamento.stl" scale="${WHEEL_SCALE} ${WHEEL_SCALE} ${WHEEL_SCALE}"/> -->
      </geometry>
    </collision>
  </link>
  <gazebo reference="roller_rightupback_wheel1_link">
    <material>Gazebo/Black</material>
    <mu1 value="2.5"/>
    <mu2 value="2.5"/>
    <kp value="5000"/>
    <kd value="10"/>
  </gazebo>
  <joint name="roller_rightupback_wheel1_joint" type="continuous">
    <parent link="wheel1_link"/>
    <child link="roller_rightupback_wheel1_link"/>
    <axis xyz="0 0 1"/>
    <origin rpy="-1.570796326794896 0 -2.82743" xyz="-0.0304984623207264 -0.0099040024057254 -0.008531038411392"/>
    <!--<dynamics damping="0.001"/>-->
  </joint>
  <link name="roller_leftupback_wheel1_link">
    <inertial>
      <origin xyz="0 0 0"/>
      <mass value="0.1"/>
      <inertia ixx="7.0710067480021846e-06" ixy="0.0" ixz="0.0" iyy="7.0710067480021846e-06" iyz="0.0" izz="3.4517509961418232e-06"/>
    </inertial>
    <visual>
      <geometry>
        <mesh filename="package://robotino_roller/description/mesh/roller01.stl"/>
        <!-- <mesh filename="package://robotino_roller/description/mesh/rolamento.stl" scale="${WHEEL_SCALE} ${WHEEL_SCALE} ${WHEEL_SCALE}"/> -->
      </geometry>
    </visual>
    <collision>
      <geometry>
        <mesh filename="package://robotino_roller/description/mesh/roller01.stl"/>
        <!-- <mesh filename="package://robotino_roller/description/mesh/rolamento.stl" scale="${WHEEL_SCALE} ${WHEEL_SCALE} ${WHEEL_SCALE}"/> -->
      </geometry>
    </collision>
  </link>
  <gazebo reference="roller_leftupback_wheel1_link">
    <material>Gazebo/Black</material>
    <mu1 value="2.5"/>
    <mu2 value="2.5"/>
    <kp value="5000"/>
    <kd value="10"/>
  </gazebo>
  <joint name="roller_leftupback_wheel1_joint" type="continuous">
    <parent link="wheel1_link"/>
    <child link="roller_leftupback_wheel1_link"/>
    <axis xyz="0 0 1"/>
    <origin rpy="-1.570796326794896 0 2.82743" xyz="0.0304984623207264 -0.0099040024057254 -0.008531038411392"/>
    <!--<dynamics damping="0.001"/>-->
  </joint>
  <link name="roller_rightdownback_wheel1_link">
    <inertial>
      <origin xyz="0 0 0"/>
      <mass value="0.1"/>
      <inertia ixx="7.0710067480021846e-06" ixy="0.0" ixz="0.0" iyy="7.0710067480021846e-06" iyz="0.0" izz="3.4517509961418232e-06"/>
    </inertial>
    <visual>
      <geometry>
        <mesh filename="package://robotino_roller/description/mesh/roller01.stl"/>
        <!-- <mesh filename="package://robotino_roller/description/mesh/rolamento.stl" scale="${WHEEL_SCALE} ${WHEEL_SCALE} ${WHEEL_SCALE}"/> -->
      </geometry>
    </visual>
    <collision>
      <geometry>
        <mesh filename="package://robotino_roller/description/mesh/roller01.stl"/>
        <!-- <mesh filename="package://robotino_roller/description/mesh/rolamento.stl" scale="${WHEEL_SCALE} ${WHEEL_SCALE} ${WHEEL_SCALE}"/> -->
      </geometry>
    </collision>
  </link>
  <gazebo reference="roller_rightdownback_wheel1_link">
    <material>Gazebo/Black</material>
    <mu1 value="2.5"/>
    <mu2 value="2.5"/>
    <kp value="5000"/>
    <kd value="10"/>
  </gazebo>
  <joint name="roller_rightdownback_wheel1_joint" type="continuous">
    <parent link="wheel1_link"/>
    <child link="roller_rightdownback_wheel1_link"/>
    <axis xyz="0 0 1"/>
    <origin rpy="-1.570796326794896 0 -0.959931" xyz="-0.018848262990169198 0.0259530184171566 -0.008531038411392"/>
    <!--<dynamics damping="0.001"/>-->
  </joint>
  <link name="roller_lefttdownback_wheel1_link">
    <inertial>
      <origin xyz="0 0 0"/>
      <mass value="0.1"/>
      <inertia ixx="7.0710067480021846e-06" ixy="0.0" ixz="0.0" iyy="7.0710067480021846e-06" iyz="0.0" izz="3.4517509961418232e-06"/>
    </inertial>
    <visual>
      <geometry>
        <mesh filename="package://robotino_roller/description/mesh/roller01.stl"/>
        <!-- <mesh filename="package://robotino_roller/description/mesh/rolamento.stl" scale="${WHEEL_SCALE} ${WHEEL_SCALE} ${WHEEL_SCALE}"/> -->
      </geometry>
    </visual>
    <collision>
      <geometry>
        <mesh filename="package://robotino_roller/description/mesh/roller01.stl"/>
        <!-- <mesh filename="package://robotino_roller/description/mesh/rolamento.stl" scale="${WHEEL_SCALE} ${WHEEL_SCALE} ${WHEEL_SCALE}"/> -->
      </geometry>
    </collision>
  </link>
  <gazebo reference="roller_lefttdownback_wheel1_link">
    <material>Gazebo/Black</material>
    <mu1 value="2.5"/>
    <mu2 value="2.5"/>
    <kp value="5000"/>
    <kd value="10"/>
  </gazebo>
  <joint name="roller_lefttdownback_wheel1_joint" type="continuous">
    <parent link="wheel1_link"/>
    <child link="roller_lefttdownback_wheel1_link"/>
    <axis xyz="0 0 1"/>
    <origin rpy="-1.570796326794896 0 0.959931" xyz="0.018848262990169198 0.0259530184171566 -0.008531038411392"/>
    <!--<dynamics damping="0.001"/>-->
  </joint>
  <transmission name="wheel1_transmission">
    <type>transmission_interface/SimpleTransmission</type>
    <joint name="wheel1_joint">
      <hardwareInterface>hardware_interface/EffortJointInterface</hardwareInterface>
    </joint>
    <actuator name="wheel1_motor">
      <hardwareInterface>hardware_interface/EffortJointInterface</hardwareInterface>
      <mechanicalReduction>1</mechanicalReduction>
    </actuator>
  </transmission>
  <link name="wheel2_link">
    <inertial>
      <origin xyz="0 0 0"/>
      <mass value="1.26"/>
      <inertia ixx="0.000672" ixy="0.0" ixz="0.0" iyy="0.000672" iyz="0.0" izz="0.001008"/>
    </inertial>
    <visual>
      <geometry>
        <mesh filename="package://robotino_roller/description/mesh/rim01.stl"/>
        <!-- <mesh filename="package://robotino_roller/description/mesh/roda.stl" scale="${WHEEL_SCALE} ${WHEEL_SCALE} ${WHEEL_SCALE}"/> -->
      </geometry>
    </visual>
    <collision>
      <geometry>
        <mesh filename="package://robotino_roller/description/mesh/rim01.stl"/>
        <!-- <mesh filename="package://robotino_roller/description/mesh/roda.stl" scale="${WHEEL_SCALE} ${WHEEL_SCALE} ${WHEEL_SCALE}"/> -->
      </geometry>
    </collision>
  </link>
  <joint name="wheel2_joint" type="continuous">
    <parent link="chassis_link"/>
    <child link="wheel2_link"/>
    <origin rpy="1.570795 0 3.6651883333333335" xyz="0.065 -0.11 0.04"/>
    <axis xyz="0 0 1"/>
  </joint>
  <gazebo reference="wheel2_link">
    <material>Gazebo/Yellow</material>
    <turnGravityOff>false</turnGravityOff>
  </gazebo>
  <link name="roller_upfront_wheel2_link">
    <inertial>
      <origin xyz="0 0 0"/>
      <mass value="0.1"/>
      <inertia ixx="7.0710067480021846e-06" ixy="0.0" ixz="0.0" iyy="7.0710067480021846e-06" iyz="0.0" izz="3.4517509961418232e-06"/>
    </inertial>
    <visual>
      <geometry>
        <mesh filename="package://robotino_roller/description/mesh/roller01.stl"/>
        <!-- <mesh filename="package://robotino_roller/description/mesh/rolamento.stl" scale="${WHEEL_SCALE} ${WHEEL_SCALE} ${WHEEL_SCALE}"/> -->
      </geometry>
    </visual>
    <collision>
      <geometry>
        <mesh filename="package://robotino_roller/description/mesh/roller01.stl"/>
        <!-- <mesh filename="package://robotino_roller/description/mesh/rolamento.stl" scale="${WHEEL_SCALE} ${WHEEL_SCALE} ${WHEEL_SCALE}"/> -->
      </geometry>
    </collision>
  </link>
  <gazebo reference="roller_upfront_wheel2_link">
    <material>Gazebo/Black</material>
    <mu1 value="2.5"/>
    <mu2 value="2.5"/>
    <kp value="5000"/>
    <kd value="10"/>
  </gazebo>
  <joint name="roller_upfront_wheel2_joint" type="continuous">
    <parent link="wheel2_link"/>
    <child link="roller_upfront_wheel2_link"/>
    <axis xyz="0 0 1"/>
    <origin rpy="-1.570796326794896 0 1.570796326794896" xyz="0.0 0.0320713725278268 0.007331361134789999"/>
    <!--<dynamics damping="0.001"/>-->
  </joint>
  <link name="roller_rightupfront_wheel2_link">
    <inertial>
      <origin xyz="0 0 0"/>
      <mass value="0.1"/>
      <inertia ixx="7.0710067480021846e-06" ixy="0.0" ixz="0.0" iyy="7.0710067480021846e-06" iyz="0.0" izz="3.4517509961418232e-06"/>
    </inertial>
    <visual>
      <geometry>
        <mesh filename="package://robotino_roller/description/mesh/roller01.stl"/>
        <!-- <mesh filename="package://robotino_roller/description/mesh/rolamento.stl" scale="${WHEEL_SCALE} ${WHEEL_SCALE} ${WHEEL_SCALE}"/> -->
      </geometry>
    </visual>
    <collision>
      <geometry>
        <mesh filename="package://robotino_roller/description/mesh/roller01.stl"/>
        <!-- <mesh filename="package://robotino_roller/description/mesh/rolamento.stl" scale="${WHEEL_SCALE} ${WHEEL_SCALE} ${WHEEL_SCALE}"/> -->
      </geometry>
    </collision>
  </link>
  <gazebo reference="roller_rightupfront_wheel2_link">
    <material>Gazebo/Black</material>
    <mu1 value="2.5"/>
    <mu2 value="2.5"/>
    <kp value="5000"/>
    <kd value="10"/>
  </gazebo>
  <joint name="roller_rightupfront_wheel2_joint" type="continuous">
    <parent link="wheel2_link"/>
    <child link="roller_rightupfront_wheel2_link"/>
    <axis xyz="0 0 1"/>
    <origin rpy="-1.570796326794896 0 -2.82743" xyz="0.0304984623207264 0.0099040024057254 0.007331361134789999"/>
    <!--<dynamics damping="0.001"/>-->
  </joint>
  <link name="roller_leftupfront_wheel2_link">
    <inertial>
      <origin xyz="0 0 0"/>
      <mass value="0.1"/>
      <inertia ixx="7.0710067480021846e-06" ixy="0.0" ixz="0.0" iyy="7.0710067480021846e-06" iyz="0.0" izz="3.4517509961418232e-06"/>
    </inertial>
    <visual>
      <geometry>
        <mesh filename="package://robotino_roller/description/mesh/roller01.stl"/>
        <!-- <mesh filename="package://robotino_roller/description/mesh/rolamento.stl" scale="${WHEEL_SCALE} ${WHEEL_SCALE} ${WHEEL_SCALE}"/> -->
      </geometry>
    </visual>
    <collision>
      <geometry>
        <mesh filename="package://robotino_roller/description/mesh/roller01.stl"/>
        <!-- <mesh filename="package://robotino_roller/description/mesh/rolamento.stl" scale="${WHEEL_SCALE} ${WHEEL_SCALE} ${WHEEL_SCALE}"/> -->
      </geometry>
    </collision>
  </link>
  <gazebo reference="roller_leftupfront_wheel2_link">
    <material>Gazebo/Black</material>
    <mu1 value="2.5"/>
    <mu2 value="2.5"/>
    <kp value="5000"/>
    <kd value="10"/>
  </gazebo>
  <joint name="roller_leftupfront_wheel2_joint" type="continuous">
    <parent link="wheel2_link"/>
    <child link="roller_leftupfront_wheel2_link"/>
    <axis xyz="0 0 1"/>
    <origin rpy="-1.570796326794896 0 2.82743" xyz="-0.0304984623207264 0.0099040024057254 0.007331361134789999"/>
    <!--<dynamics damping="0.001"/>-->
  </joint>
  <link name="roller_rightdownfront_wheel2_link">
    <inertial>
      <origin xyz="0 0 0"/>
      <mass value="0.1"/>
      <inertia ixx="7.0710067480021846e-06" ixy="0.0" ixz="0.0" iyy="7.0710067480021846e-06" iyz="0.0" izz="3.4517509961418232e-06"/>
    </inertial>
    <visual>
      <geometry>
        <mesh filename="package://robotino_roller/description/mesh/roller01.stl"/>
        <!-- <mesh filename="package://robotino_roller/description/mesh/rolamento.stl" scale="${WHEEL_SCALE} ${WHEEL_SCALE} ${WHEEL_SCALE}"/> -->
      </geometry>
    </visual>
    <collision>
      <geometry>
        <mesh filename="package://robotino_roller/description/mesh/roller01.stl"/>
        <!-- <mesh filename="package://robotino_roller/description/mesh/rolamento.stl" scale="${WHEEL_SCALE} ${WHEEL_SCALE} ${WHEEL_SCALE}"/> -->
      </geometry>
    </collision>
  </link>
  <gazebo reference="roller_rightdownfront_wheel2_link">
    <material>Gazebo/Black</material>
    <mu1 value="2.5"/>
    <mu2 value="2.5"/>
    <kp value="5000"/>
    <kd value="10"/>
  </gazebo>
  <joint name="roller_rightdownfront_wheel2_joint" type="continuous">
    <parent link="wheel2_link"/>
    <child link="roller_rightdownfront_wheel2_link"/>
    <axis xyz="0 0 1"/>
    <origin rpy="-1.570796326794896 0 -0.959931" xyz="0.018848262990169198 -0.0259530184171566 0.007331361134789999"/>
    <!--<dynamics damping="0.001"/>-->
  </joint>
  <link name="roller_lefttdownfront_wheel2_link">
    <inertial>
      <origin xyz="0 0 0"/>
      <mass value="0.1"/>
      <inertia ixx="7.0710067480021846e-06" ixy="0.0" ixz="0.0" iyy="7.0710067480021846e-06" iyz="0.0" izz="3.4517509961418232e-06"/>
    </inertial>
    <visual>
      <geometry>
        <mesh filename="package://robotino_roller/description/mesh/roller01.stl"/>
        <!-- <mesh filename="package://robotino_roller/description/mesh/rolamento.stl" scale="${WHEEL_SCALE} ${WHEEL_SCALE} ${WHEEL_SCALE}"/> -->
      </geometry>
    </visual>
    <collision>
      <geometry>
        <mesh filename="package://robotino_roller/description/mesh/roller01.stl"/>
        <!-- <mesh filename="package://robotino_roller/description/mesh/rolamento.stl" scale="${WHEEL_SCALE} ${WHEEL_SCALE} ${WHEEL_SCALE}"/> -->
      </geometry>
    </collision>
  </link>
  <gazebo reference="roller_lefttdownfront_wheel2_link">
    <material>Gazebo/Black</material>
    <mu1 value="2.5"/>
    <mu2 value="2.5"/>
    <kp value="5000"/>
    <kd value="10"/>
  </gazebo>
  <joint name="roller_lefttdownfront_wheel2_joint" type="continuous">
    <parent link="wheel2_link"/>
    <child link="roller_lefttdownfront_wheel2_link"/>
    <axis xyz="0 0 1"/>
    <origin rpy="-1.570796326794896 0 0.959931" xyz="-0.018848262990169198 -0.0259530184171566 0.007331361134789999"/>
    <!--<dynamics damping="0.001"/>-->
  </joint>
  <link name="roller_upback_wheel2_link">
    <inertial>
      <origin xyz="0 0 0"/>
      <mass value="0.1"/>
      <inertia ixx="7.0710067480021846e-06" ixy="0.0" ixz="0.0" iyy="7.0710067480021846e-06" iyz="0.0" izz="3.4517509961418232e-06"/>
    </inertial>
    <visual>
      <geometry>
        <mesh filename="package://robotino_roller/description/mesh/roller01.stl"/>
        <!-- <mesh filename="package://robotino_roller/description/mesh/rolamento.stl" scale="${WHEEL_SCALE} ${WHEEL_SCALE} ${WHEEL_SCALE}"/> -->
      </geometry>
    </visual>
    <collision>
      <geometry>
        <mesh filename="package://robotino_roller/description/mesh/roller01.stl"/>
        <!-- <mesh filename="package://robotino_roller/description/mesh/rolamento.stl" scale="${WHEEL_SCALE} ${WHEEL_SCALE} ${WHEEL_SCALE}"/> -->
      </geometry>
    </collision>
  </link>
  <gazebo reference="roller_upback_wheel2_link">
    <material>Gazebo/Black</material>
    <mu1 value="2.5"/>
    <mu2 value="2.5"/>
    <kp value="5000"/>
    <kd value="10"/>
  </gazebo>
  <joint name="roller_upback_wheel2_joint" type="continuous">
    <parent link="wheel2_link"/>
    <child link="roller_upback_wheel2_link"/>
    <axis xyz="0 0 1"/>
    <origin rpy="-1.570796326794896 0 1.570796326794896" xyz="0.0 -0.0320713725278268 -0.008531038411392"/>
    <!--<dynamics damping="0.001"/>-->
  </joint>
  <link name="roller_rightupback_wheel2_link">
    <inertial>
      <origin xyz="0 0 0"/>
      <mass value="0.1"/>
      <inertia ixx="7.0710067480021846e-06" ixy="0.0" ixz="0.0" iyy="7.0710067480021846e-06" iyz="0.0" izz="3.4517509961418232e-06"/>
    </inertial>
    <visual>
      <geometry>
        <mesh filename="package://robotino_roller/description/mesh/roller01.stl"/>
        <!-- <mesh filename="package://robotino_roller/description/mesh/rolamento.stl" scale="${WHEEL_SCALE} ${WHEEL_SCALE} ${WHEEL_SCALE}"/> -->
      </geometry>
    </visual>
    <collision>
      <geometry>
        <mesh filename="package://robotino_roller/description/mesh/roller01.stl"/>
        <!-- <mesh filename="package://robotino_roller/description/mesh/rolamento.stl" scale="${WHEEL_SCALE} ${WHEEL_SCALE} ${WHEEL_SCALE}"/> -->
      </geometry>
    </collision>
  </link>
  <gazebo reference="roller_rightupback_wheel2_link">
    <material>Gazebo/Black</material>
    <mu1 value="2.5"/>
    <mu2 value="2.5"/>
    <kp value="5000"/>
    <kd value="10"/>
  </gazebo>
  <joint name="roller_rightupback_wheel2_joint" type="continuous">
    <parent link="wheel2_link"/>
    <child link="roller_rightupback_wheel2_link"/>
    <axis xyz="0 0 1"/>
    <origin rpy="-1.570796326794896 0 -2.82743" xyz="-0.0304984623207264 -0.0099040024057254 -0.008531038411392"/>
    <!--<dynamics damping="0.001"/>-->
  </joint>
  <link name="roller_leftupback_wheel2_link">
    <inertial>
      <origin xyz="0 0 0"/>
      <mass value="0.1"/>
      <inertia ixx="7.0710067480021846e-06" ixy="0.0" ixz="0.0" iyy="7.0710067480021846e-06" iyz="0.0" izz="3.4517509961418232e-06"/>
    </inertial>
    <visual>
      <geometry>
        <mesh filename="package://robotino_roller/description/mesh/roller01.stl"/>
        <!-- <mesh filename="package://robotino_roller/description/mesh/rolamento.stl" scale="${WHEEL_SCALE} ${WHEEL_SCALE} ${WHEEL_SCALE}"/> -->
      </geometry>
    </visual>
    <collision>
      <geometry>
        <mesh filename="package://robotino_roller/description/mesh/roller01.stl"/>
        <!-- <mesh filename="package://robotino_roller/description/mesh/rolamento.stl" scale="${WHEEL_SCALE} ${WHEEL_SCALE} ${WHEEL_SCALE}"/> -->
      </geometry>
    </collision>
  </link>
  <gazebo reference="roller_leftupback_wheel2_link">
    <material>Gazebo/Black</material>
    <mu1 value="2.5"/>
    <mu2 value="2.5"/>
    <kp value="5000"/>
    <kd value="10"/>
  </gazebo>
  <joint name="roller_leftupback_wheel2_joint" type="continuous">
    <parent link="wheel2_link"/>
    <child link="roller_leftupback_wheel2_link"/>
    <axis xyz="0 0 1"/>
    <origin rpy="-1.570796326794896 0 2.82743" xyz="0.0304984623207264 -0.0099040024057254 -0.008531038411392"/>
    <!--<dynamics damping="0.001"/>-->
  </joint>
  <link name="roller_rightdownback_wheel2_link">
    <inertial>
      <origin xyz="0 0 0"/>
      <mass value="0.1"/>
      <inertia ixx="7.0710067480021846e-06" ixy="0.0" ixz="0.0" iyy="7.0710067480021846e-06" iyz="0.0" izz="3.4517509961418232e-06"/>
    </inertial>
    <visual>
      <geometry>
        <mesh filename="package://robotino_roller/description/mesh/roller01.stl"/>
        <!-- <mesh filename="package://robotino_roller/description/mesh/rolamento.stl" scale="${WHEEL_SCALE} ${WHEEL_SCALE} ${WHEEL_SCALE}"/> -->
      </geometry>
    </visual>
    <collision>
      <geometry>
        <mesh filename="package://robotino_roller/description/mesh/roller01.stl"/>
        <!-- <mesh filename="package://robotino_roller/description/mesh/rolamento.stl" scale="${WHEEL_SCALE} ${WHEEL_SCALE} ${WHEEL_SCALE}"/> -->
      </geometry>
    </collision>
  </link>
  <gazebo reference="roller_rightdownback_wheel2_link">
    <material>Gazebo/Black</material>
    <mu1 value="2.5"/>
    <mu2 value="2.5"/>
    <kp value="5000"/>
    <kd value="10"/>
  </gazebo>
  <joint name="roller_rightdownback_wheel2_joint" type="continuous">
    <parent link="wheel2_link"/>
    <child link="roller_rightdownback_wheel2_link"/>
    <axis xyz="0 0 1"/>
    <origin rpy="-1.570796326794896 0 -0.959931" xyz="-0.018848262990169198 0.0259530184171566 -0.008531038411392"/>
    <!--<dynamics damping="0.001"/>-->
  </joint>
  <link name="roller_lefttdownback_wheel2_link">
    <inertial>
      <origin xyz="0 0 0"/>
      <mass value="0.1"/>
      <inertia ixx="7.0710067480021846e-06" ixy="0.0" ixz="0.0" iyy="7.0710067480021846e-06" iyz="0.0" izz="3.4517509961418232e-06"/>
    </inertial>
    <visual>
      <geometry>
        <mesh filename="package://robotino_roller/description/mesh/roller01.stl"/>
        <!-- <mesh filename="package://robotino_roller/description/mesh/rolamento.stl" scale="${WHEEL_SCALE} ${WHEEL_SCALE} ${WHEEL_SCALE}"/> -->
      </geometry>
    </visual>
    <collision>
      <geometry>
        <mesh filename="package://robotino_roller/description/mesh/roller01.stl"/>
        <!-- <mesh filename="package://robotino_roller/description/mesh/rolamento.stl" scale="${WHEEL_SCALE} ${WHEEL_SCALE} ${WHEEL_SCALE}"/> -->
      </geometry>
    </collision>
  </link>
  <gazebo reference="roller_lefttdownback_wheel2_link">
    <material>Gazebo/Black</material>
    <mu1 value="2.5"/>
    <mu2 value="2.5"/>
    <kp value="5000"/>
    <kd value="10"/>
  </gazebo>
  <joint name="roller_lefttdownback_wheel2_joint" type="continuous">
    <parent link="wheel2_link"/>
    <child link="roller_lefttdownback_wheel2_link"/>
    <axis xyz="0 0 1"/>
    <origin rpy="-1.570796326794896 0 0.959931" xyz="0.018848262990169198 0.0259530184171566 -0.008531038411392"/>
    <!--<dynamics damping="0.001"/>-->
  </joint>
  <transmission name="wheel2_transmission">
    <type>transmission_interface/SimpleTransmission</type>
    <joint name="wheel2_joint">
      <hardwareInterface>hardware_interface/EffortJointInterface</hardwareInterface>
    </joint>
    <actuator name="wheel2_motor">
      <hardwareInterface>hardware_interface/EffortJointInterface</hardwareInterface>
      <mechanicalReduction>1</mechanicalReduction>
    </actuator>
  </transmission>
  <!-- <xacro:macro name="wheel" params="parent name *origin *axis">
        <link name="${name}_link">
            <xacro:inertial_cylinder mass="${WHEEL_MASS}" height="${WHEEL_HEIGHT}" radius="${WHEEL_RADIUS}">
                <origin xyz="0 0 0"/>
            </xacro:inertial_cylinder>
            <visual>
                <origin xyz="0 0 0" rpy="0 0 0"/>
                <geometry>
                    <mesh filename="package://robotino_sim/description/meshes/robotino_wheel.dae" scale="${M_SCALE} ${M_SCALE} ${M_SCALE}"/>
                </geometry>
            </visual>
            <collision>
                <origin xyz="0 0 0" rpy="0 0 0"/>
                <geometry>
                    <mesh filename="package://robotino_sim/description/meshes/robotino_wheel.dae" scale="${M_SCALE} ${M_SCALE} ${M_SCALE}"/>
                </geometry>
            </collision>
        </link>
        <gazebo reference="${name}_link">
            <material>Gazebo/Yellow</material>
            <turnGravityOff>false</turnGravityOff>
        </gazebo>
        <joint name="${name}_joint" type="continuous">
            <xacro:insert_block name="origin" />
            <xacro:insert_block name="axis"/>
            <parent link="${parent}"/>
            <child link="${name}_link"/>
        </joint>
        <transmission name="${name}_joint_trans">
            <type>transmission_interface/SimpleTransmission</type>
            <joint name="${name}_joint">
                <hardwareInterface>hardware_interface/EffortJointInterface</hardwareInterface>
            </joint>
            <actuator name="${name}_motor">
                <hardwareInterface>hardware_interface/EffortJointInterface</hardwareInterface>
                <mechanicalReduction>1</mechanicalReduction>
            </actuator>
        </transmission>
    </xacro:macro>

    <xacro:wheel name="wheel0o" parent="base_link">
        <origin xyz="0.065 0.11 0.08" rpy="0 ${M_PI/2} ${M_PI/3}"/>
        <axis xyz="-1 0 0"/>
    </xacro:wheel>

    <xacro:wheel name="wheel1o" parent="base_link">
        <origin xyz="-0.13 0 0.08" rpy="0 ${M_PI/2} 0"/>
        <axis xyz="1 0 0"/>
    </xacro:wheel>

    <xacro:wheel name="wheel2o" parent="base_link">
        <origin xyz="0.065 -0.11 0.08" rpy="0 ${M_PI/2} -${M_PI/3}"/>
        <axis xyz="-1 0 0"/>
    </xacro:wheel> -->
  <gazebo>
    <plugin filename="libgazebo_ros_control.so" name="gazebo_ros_control"/>
  </gazebo>
</robot>

