<?xml version="1.0" ?>
<robot xmlns:xacro="http://www.ros.org/wiki/xacro">

	<xacro:macro name="wheel_macro" params="parent name *origin *axis">

		<link name="${name}_link">
			<xacro:inertial_cylinder mass="${WHEEL_MASS}" height="${WHEEL_HEIGHT}" radius="${WHEEL_RADIUS}">
				<origin xyz="0 0 0"/>
			</xacro:inertial_cylinder>
			<visual>
				<geometry>
					<mesh filename="package://robotino_roller/description/mesh/rim01.stl"/>
					<!-- <mesh filename="package://robotino_roller/description/mesh/roda.stl" scale="${WHEEL_SCALE} ${WHEEL_SCALE} ${WHEEL_SCALE}"/> -->
				</geometry>
			</visual>
			<collision>
				<geometry>
					<mesh filename="package://robotino_roller/description/mesh/rim01.stl"/>
					<!-- <mesh filename="package://robotino_roller/description/mesh/roda.stl" scale="${WHEEL_SCALE} ${WHEEL_SCALE} ${WHEEL_SCALE}"/> -->
				</geometry>
			</collision>
		</link>

		<joint name="${name}_joint" type="continuous">
			<parent link="${parent}" />
			<child link="${name}_link" />
			<xacro:insert_block name="origin" />
			<xacro:insert_block name="axis" />
		</joint>

		<gazebo reference="${name}_link">
			<material>Gazebo/Yellow</material>
			<turnGravityOff>false</turnGravityOff>
		</gazebo>

		<!--- Rollers -->
		<xacro:roller_macro parent="${name}" name="upfront" xyz="${[0, 0.02406, 0.0055]}" rpy="-1.570796326794896 0 1.570796326794896" />
		<xacro:roller_macro parent="${name}" name="rightupfront" xyz="${[0.02288, 0.00743, 0.0055]}" rpy="-1.570796326794896 0 -2.82743" />
		<xacro:roller_macro parent="${name}" name="leftupfront" xyz="${[-0.02288,  0.00743, 0.0055]}" rpy="-1.570796326794896 0 2.82743" />
		<xacro:roller_macro parent="${name}" name="rightdownfront" xyz="${[0.01414, -0.01947, 0.0055]}" rpy="-1.570796326794896 0 -0.959931" />
		<xacro:roller_macro parent="${name}" name="lefttdownfront" xyz="${[-0.01414, -0.01947, 0.0055]}" rpy="-1.570796326794896 0 0.959931" />

		<!---Back part of the wheel -->
		<xacro:roller_macro parent="${name}" name="upback" xyz="${[0, -0.02406, -0.0064]}" rpy="-1.570796326794896 0 1.570796326794896" />
		<xacro:roller_macro parent="${name}" name="rightupback" xyz="${[-0.02288, -0.00743, -0.0064]}" rpy="-1.570796326794896 0 -2.82743" />
		<xacro:roller_macro parent="${name}" name="leftupback" xyz="${[0.02288, -0.00743, -0.0064]}" rpy="-1.570796326794896 0 2.82743" />
		<xacro:roller_macro parent="${name}" name="rightdownback" xyz="${[-0.01414, 0.01947, -0.0064]}" rpy="-1.570796326794896 0 -0.959931" />
		<xacro:roller_macro parent="${name}" name="lefttdownback" xyz="${[0.01414, 0.01947, -0.0064]}" rpy="-1.570796326794896 0 0.959931" />

		<transmission name="${name}_transmission">
			<type>transmission_interface/SimpleTransmission</type>
			<joint name="${name}_joint">
				<hardwareInterface>hardware_interface/EffortJointInterface</hardwareInterface>
			</joint>
			<actuator name="${name}_motor">
				<hardwareInterface>hardware_interface/EffortJointInterface</hardwareInterface>
				<mechanicalReduction>1</mechanicalReduction>
			</actuator>
		</transmission>

	</xacro:macro>

	<xacro:macro name="roller_macro" params="parent name xyz rpy">

		<link name="roller_${name}_${parent}_link">
			<xacro:inertial_cylinder mass="${ROLLER_MASS}" height="${ROLLER_HEIGHT*WHEEL_SCALE}" radius="${ROLLER_RADIUS*WHEEL_SCALE}">
				<origin xyz="0 0 0"/>
			</xacro:inertial_cylinder>
			<visual>
				<geometry>
					<mesh filename="package://robotino_roller/description/mesh/roller01.stl"/>
					<!-- <mesh filename="package://robotino_roller/description/mesh/rolamento.stl" scale="${WHEEL_SCALE} ${WHEEL_SCALE} ${WHEEL_SCALE}"/> -->
				</geometry>
			</visual>
			<collision>
				<geometry>
					<mesh filename="package://robotino_roller/description/mesh/roller01.stl"/>
					<!-- <mesh filename="package://robotino_roller/description/mesh/rolamento.stl" scale="${WHEEL_SCALE} ${WHEEL_SCALE} ${WHEEL_SCALE}"/> -->
				</geometry>
			</collision>
		</link>

		<gazebo reference="roller_${name}_${parent}_link">
			<material>Gazebo/Black</material>
			<mu1 value="2.5" />
			<mu2 value="2.5" />
			<kp value="5000" />
			<kd value="10" />
		</gazebo>

		<joint name="roller_${name}_${parent}_joint" type="continuous">
			<parent link="${parent}_link"/>
			<child link="roller_${name}_${parent}_link"/>
			<axis xyz="0 0 1"/>
			<origin xyz="${xyz[0]*WHEEL_SCALE} ${xyz[1]*WHEEL_SCALE} ${xyz[2]*WHEEL_SCALE}" rpy="${rpy}"/>
			<!--<dynamics damping="0.001"/>-->
		</joint>
	</xacro:macro>

</robot>
